<mujoco model="hector_gazebo">
  <compiler angle="radian" meshdir="../meshes/" autolimits="true"/>
  <statistic meansize="0.142362" extent="0.723933" center="-0.000164968 0.000944368 -0.0375921"/>
  <asset>
    <mesh name="l_wheel_link" file="l_wheel_link.STL"/>
    <mesh name="r_wheel_link" file="r_wheel_link.STL"/>
    <mesh name="l_f_mt_link" file="l_f_mt_link.STL"/>
    <mesh name="l_b_mt_link" file="l_b_mt_link.STL"/>
    <mesh name="r_f_mt_link" file="r_f_mt_link.STL"/>
    <mesh name="r_b_mt_link" file="r_b_mt_link.STL"/>
  </asset>
  <worldbody>
    <body name="base_link">
      <inertial pos="-0.000420506 -1.108e-05 -0.0249286" quat="0.498686 0.49878 -0.502212 0.500314" mass="7.01356" diaginertia="0.22301 0.16472 0.0822435"/>
      <joint name="base_link_free_joint" type="free"/>
      <geom size="0.14 0.14 0.06" type="box" contype="0" conaffinity="0" group="1" density="0" rgba="0.75294 0.75294 0.75294 1"/>
      <geom size="0.14 0.14 0.06" type="box" rgba="0.75294 0.75294 0.75294 1"/>
      <geom pos="0.054 0.2025 0" type="mesh" contype="0" conaffinity="0" group="1" density="0" rgba="0.89804 0.91765 0.92941 1" mesh="l_f_mt_link"/>
      <geom pos="0.054 0.2025 0" type="mesh" rgba="0.89804 0.91765 0.92941 1" mesh="l_f_mt_link"/>
      <geom pos="-0.054 0.2025 0" type="mesh" contype="0" conaffinity="0" group="1" density="0" rgba="0.89804 0.91765 0.92941 1" mesh="l_b_mt_link"/>
      <geom pos="-0.054 0.2025 0" type="mesh" rgba="0.89804 0.91765 0.92941 1" mesh="l_b_mt_link"/>
      <geom pos="0.054 -0.2025 0" type="mesh" contype="0" conaffinity="0" group="1" density="0" rgba="0.89804 0.91765 0.92941 1" mesh="r_f_mt_link"/>
      <geom pos="0.054 -0.2025 0" type="mesh" rgba="0.89804 0.91765 0.92941 1" mesh="r_f_mt_link"/>
      <geom pos="-0.054 -0.2025 0" type="mesh" contype="0" conaffinity="0" group="1" density="0" rgba="0.89804 0.91765 0.92941 1" mesh="r_b_mt_link"/>
      <geom pos="-0.054 -0.2025 0" type="mesh" rgba="0.89804 0.91765 0.92941 1" mesh="r_b_mt_link"/>
      <geom size="0.0005 0.0005 0.0005" type="box" contype="0" conaffinity="0" group="1" density="0"/>
      <geom size="0.0005 0.0005 0.0005" type="box"/>
      <body name="l_mt_link" pos="0 0.16 0">
        <inertial pos="0 0 0" quat="0.820473 0.339851 -0.17592 0.424708" mass="0.0001" diaginertia="1e-10 1e-10 1e-10"/>
        <joint name="l_mt_joint" pos="0 0 0" axis="0 1 0" range="-0.8 0.8"/>
        <geom size="0.0125 0.0125 0.04" pos="0 0 -0.04" type="box" contype="0" conaffinity="0" group="1" density="0" rgba="0.3 0.4 0.5 1"/>
        <geom size="0.0125 0.0125 0.04" pos="0 0 -0.04" type="box" rgba="0.3 0.4 0.5 1"/>
        <body name="l_p_link" pos="0 0 -0.08">
          <inertial pos="0 0 0" quat="0.820473 0.339851 -0.17592 0.424708" mass="0.0001" diaginertia="1e-10 1e-10 1e-10"/>
          <joint name="l_p_joint" pos="0 0 0" axis="0 0 1" type="slide" range="-0.18 0.08"/>
          <geom size="0.0125 0.0125 0.04" pos="0 0.03 -0.04" type="box" contype="0" conaffinity="0" group="1" density="0" rgba="0.4 0.3 0.2 1"/>
          <geom size="0.0125 0.0125 0.04" pos="0 0.03 -0.04" type="box" rgba="0.4 0.3 0.2 1"/>
          <body name="l_wheel_link" pos="0 0.1 -0.091525">
            <inertial pos="6.7739e-06 -0.003652 4.26e-06" quat="0.270602 0.653253 0.653298 0.270625" mass="0.43397" diaginertia="0.0010009 0.000539513 0.000539487"/>
            <joint name="l_wheel_joint" pos="0 0 0" axis="0 1 0" range="-100000 100000"/>
            <geom type="mesh" contype="0" conaffinity="0" group="1" density="0" rgba="0 1 1 1" mesh="l_wheel_link"/>
            <geom size="0.0725 0.015" pos="0 -0.01 0" quat="0.707107 0.707107 0 0" type="cylinder" rgba="0 1 1 1"/>
          </body>
        </body>
      </body>
      <body name="r_mt_link" pos="0 -0.16 0">
        <inertial pos="0 0 0" quat="0.820473 0.339851 -0.17592 0.424708" mass="0.0001" diaginertia="1e-10 1e-10 1e-10"/>
        <joint name="r_mt_joint" pos="0 0 0" axis="0 1 0" range="-0.8 0.8"/>
        <geom size="0.0125 0.0125 0.04" pos="0 0 -0.04" type="box" contype="0" conaffinity="0" group="1" density="0" rgba="0.3 0.4 0.5 1"/>
        <geom size="0.0125 0.0125 0.04" pos="0 0 -0.04" type="box" rgba="0.3 0.4 0.5 1"/>
        <body name="r_p_link" pos="0 0 -0.08">
          <inertial pos="0 0 0" quat="0.820473 0.339851 -0.17592 0.424708" mass="0.0001" diaginertia="1e-10 1e-10 1e-10"/>
          <joint name="r_p_joint" pos="0 0 0" axis="0 0 1" type="slide" range="-0.18 0.08"/>
          <geom size="0.0125 0.0125 0.04" pos="0 -0.03 -0.04" type="box" contype="0" conaffinity="0" group="1" density="0" rgba="0.4 0.3 0.2 1"/>
          <geom size="0.0125 0.0125 0.04" pos="0 -0.03 -0.04" type="box" rgba="0.4 0.3 0.2 1"/>
          <body name="r_wheel_link" pos="0 -0.1 -0.091525">
            <inertial pos="-2.3366e-06 0.0089279 -8.278e-06" quat="0.402437 0.58143 0.581444 0.402377" mass="0.40373" diaginertia="0.00081663 0.000440363 0.000440337"/>
            <joint name="r_wheel_joint" pos="0 0 0" axis="0 1 0" range="-100000 100000"/>
            <geom type="mesh" contype="0" conaffinity="0" group="1" density="0" rgba="0.29804 0.29804 0.29804 1" mesh="r_wheel_link"/>
            <geom size="0.0725 0.015" pos="0 0.01 0" quat="0.707107 0.707107 0 0" type="cylinder" rgba="0.29804 0.29804 0.29804 1"/>
          </body>
        </body>
      </body>
    </body>
  </worldbody>
</mujoco>
