<mujoco model="pi_12dof_release_v1">
	<compiler angle="radian" meshdir="../meshes/" eulerseq="zyx" />
	<option timestep="0.001" iterations="50" solver="PGS" gravity="0 0 -9.81">
		<!-- <flag sensornoise="enable" frictionloss="enable"/> -->
	</option>
	<size njmax="500" nconmax="100" />
	<visual>
		<quality shadowsize="4096" />
		<map znear="0.05" />
	</visual>
	<default>
		<joint limited="true" />
		<motor ctrllimited="true" />
		<geom condim="4" contype="1" conaffinity="15" solref="0.001 2" friction="0.9 0.2 0.2" />
		<equality solref="0.001 2" />
		<default class="visualgeom">
			<geom material="visualgeom" condim="1" contype="0" conaffinity="0" />
		</default>
		<default class="visualgeom2">
			<geom material="visualgeom2" condim="1" contype="0" conaffinity="0" />
		</default>
		<default class="obstacle">
			<geom material="obstacle" condim="3" contype="1" conaffinity="15" />
		</default>
	</default>
	<asset>
		<texture type="skybox" builtin="gradient" rgb1="0.3 0.5 0.7" rgb2="0 0 0" width="512" height="512" />
		<texture name="texplane" type="2d" builtin="checker" rgb1=".2 .3 .4" rgb2=".1 0.15 0.2" width="512" height="512" mark="cross" markrgb=".8 .8 .8" />
		<texture name="texplane2" type="2d" builtin="checker" rgb1="1 0.3137 0.1843" rgb2="0.0 0.30196 0.38039" width="512" height="512" mark="cross" markrgb=".8 .8 .8" />
		<material name="matplane" reflectance="0." texture="texplane" texrepeat="1 1" texuniform="true" />
		<material name="matplane2" reflectance="0.1" texture="texplane2" texrepeat="1 1" texuniform="true" />
		<material name="obstacle" rgba="0.9 0.6 0.2 1" />
		<material name="visualgeom" rgba="0.5 0.9 0.2 1" />
		<material name="visualgeom2" rgba="0.5 0.9 0.2 1" />
		<mesh name="l_wheel_link" file="l_wheel_link.STL" />
		<mesh name="l_f_mt_link" file="l_f_mt_link.STL" />
		<mesh name="l_b_mt_link" file="l_b_mt_link.STL" />
		<mesh name="r_f_mt_link" file="r_f_mt_link.STL" />
		<mesh name="r_wheel_link" file="r_wheel_link.STL" />
		<mesh name="r_b_mt_link" file="r_b_mt_link.STL" />
		<hfield name="hf0" nrow="200" ncol="200" size="10 5 0.2 .1" />
	</asset>
	<worldbody>
		<light directional="true" diffuse=".4 .4 .4" specular="0.1 0.1 0.1" pos="0 0 5.0" dir="0 0 -1" castshadow="false" />
		<light directional="true" diffuse=".6 .6 .6" specular="0.2 0.2 0.2" pos="0 0 4" dir="0 0 -1" />
		<geom name="ground" type="plane" size="0 0 1" pos="0.001 0 0" quat="1 0 0 0" material="matplane" condim="1" conaffinity="15" />
		<body name="base_link" pos="0.0 0.0 0.245">
			<inertial pos="0.00242324 -5.699e-05 0.0403008" quat="0.695312 0.00968645 0.00943283 0.718581" mass="2.1609" diaginertia="0.00978249 0.00901239 0.00416199" />
			<geom size="0.14 0.14 0.06" type="box" contype="0" conaffinity="0" group="1" density="0" rgba="0.75294 0.75294 0.75294 1" />
			<geom size="0.14 0.14 0.06" type="box" rgba="0.75294 0.75294 0.75294 1" />
			<geom pos="0.054 0.2025 0" type="mesh" contype="0" conaffinity="0" group="1" density="0" rgba="0.89804 0.91765 0.92941 1" mesh="l_f_mt_link" />
			<geom pos="0.054 0.2025 0" type="mesh" rgba="0.89804 0.91765 0.92941 1" mesh="l_f_mt_link" />
			<geom pos="-0.054 0.2025 0" type="mesh" contype="0" conaffinity="0" group="1" density="0" rgba="0.89804 0.91765 0.92941 1" mesh="l_b_mt_link" />
			<geom pos="-0.054 0.2025 0" type="mesh" rgba="0.89804 0.91765 0.92941 1" mesh="l_b_mt_link" />
			<geom pos="0.054 -0.2025 0" type="mesh" contype="0" conaffinity="0" group="1" density="0" rgba="0.89804 0.91765 0.92941 1" mesh="r_f_mt_link" />
			<geom pos="0.054 -0.2025 0" type="mesh" rgba="0.89804 0.91765 0.92941 1" mesh="r_f_mt_link" />
			<geom pos="-0.054 -0.2025 0" type="mesh" contype="0" conaffinity="0" group="1" density="0" rgba="0.89804 0.91765 0.92941 1" mesh="r_b_mt_link" />
			<geom pos="-0.054 -0.2025 0" type="mesh" rgba="0.89804 0.91765 0.92941 1" mesh="r_b_mt_link" />
			<geom size="0.0005 0.0005 0.0005" type="box" contype="0" conaffinity="0" group="1" density="0" />
			<geom size="0.0005 0.0005 0.0005" type="box" />
			<joint type="slide" axis="1 0 0" limited="false" />
			<joint type="slide" axis="0 1 0" limited="false" />
			<joint type="slide" axis="0 0 1" limited="false" />
			<joint type="ball" limited="false" />
			<!-- <joint pos="0 0 0" axis="0 1 0" range="0.3 0.3000000000008"/> -->
			<site name="imu" size="0.01" pos="0.0 0 0.0" />
			<body name="l_mt_link" pos="0 0.16 0">
				<inertial pos="0 0 0" quat="0.820473 0.339851 -0.17592 0.424708" mass="0.0001" diaginertia="1e-10 1e-10 1e-10" />
				<joint name="l_mt_joint" pos="0 0 0" axis="0 1 0" range="-0.8 0.8" />
				<geom size="0.0125 0.0125 0.04" pos="0 0 -0.04" type="box" contype="0" conaffinity="0" group="1" density="0" rgba="0.3 0.4 0.5 1" />
				<geom size="0.0125 0.0125 0.04" pos="0 0 -0.04" type="box" rgba="0.3 0.4 0.5 1" />
				<body name="l_p_link" pos="0 0 -0.08">
					<inertial pos="0 0 0" quat="0.820473 0.339851 -0.17592 0.424708" mass="0.0001" diaginertia="1e-10 1e-10 1e-10" />
					<joint name="l_p_joint" pos="0 0 0" axis="0 0 1" type="slide" range="-0.18 0.08" />
					<geom size="0.0125 0.0125 0.04" pos="0 0.03 -0.04" type="box" contype="0" conaffinity="0" group="1" density="0" rgba="0.4 0.3 0.2 1" />
					<geom size="0.0125 0.0125 0.04" pos="0 0.03 -0.04" type="box" rgba="0.4 0.3 0.2 1" />
					<body name="l_wheel_link" pos="0 0.1 -0.091525">
						<inertial pos="6.7739e-06 -0.003652 4.26e-06" quat="0.270602 0.653253 0.653298 0.270625" mass="0.43397" diaginertia="0.0010009 0.000539513 0.000539487" />
						<joint name="l_wheel_joint" pos="0 0 0" axis="0 1 0" range="-100000 100000" />
						<geom type="mesh" contype="0" conaffinity="0" group="1" density="0" rgba="0 1 1 1" mesh="l_wheel_link" />
						<geom size="0.0725 0.015" pos="0 -0.01 0" quat="0.707107 0.707107 0 0" type="cylinder" rgba="0 1 1 1" />
					</body>
				</body>
			</body>
			<body name="r_mt_link" pos="0 -0.16 0">
				<inertial pos="0 0 0" quat="0.820473 0.339851 -0.17592 0.424708" mass="0.0001" diaginertia="1e-10 1e-10 1e-10" />
				<joint name="r_mt_joint" pos="0 0 0" axis="0 1 0" range="-0.8 0.8" />
				<geom size="0.0125 0.0125 0.04" pos="0 0 -0.04" type="box" contype="0" conaffinity="0" group="1" density="0" rgba="0.3 0.4 0.5 1" />
				<geom size="0.0125 0.0125 0.04" pos="0 0 -0.04" type="box" rgba="0.3 0.4 0.5 1" />
				<body name="r_p_link" pos="0 0 -0.08">
					<inertial pos="0 0 0" quat="0.820473 0.339851 -0.17592 0.424708" mass="0.0001" diaginertia="1e-10 1e-10 1e-10" />
					<joint name="r_p_joint" pos="0 0 0" axis="0 0 1" type="slide" range="-0.18 0.08" />
					<geom size="0.0125 0.0125 0.04" pos="0 -0.03 -0.04" type="box" contype="0" conaffinity="0" group="1" density="0" rgba="0.4 0.3 0.2 1" />
					<geom size="0.0125 0.0125 0.04" pos="0 -0.03 -0.04" type="box" rgba="0.4 0.3 0.2 1" />
					<body name="r_wheel_link" pos="0 -0.1 -0.091525">
						<inertial pos="-2.3366e-06 0.0089279 -8.278e-06" quat="0.402437 0.58143 0.581444 0.402377" mass="0.40373" diaginertia="0.00081663 0.000440363 0.000440337" />
						<joint name="r_wheel_joint" pos="0 0 0" axis="0 1 0" range="-100000 100000" />
						<geom type="mesh" contype="0" conaffinity="0" group="1" density="0" rgba="0.29804 0.29804 0.29804 1" mesh="r_wheel_link" />
						<geom size="0.0725 0.015" pos="0 0.01 0" quat="0.707107 0.707107 0 0" type="cylinder" rgba="0.29804 0.29804 0.29804 1" />
					</body>
				</body>
			</body>
		</body>
	</worldbody>
	<actuator>
		<motor name="r_mt_joint" joint="r_mt_joint" gear="1" ctrllimited="true" ctrlrange="-200 200" />
		<motor name="r_p_joint" joint="r_p_joint" gear="1" ctrllimited="true" ctrlrange="-200 200" />
		<motor name="r_wheel_joint" joint="r_wheel_joint" gear="1" ctrllimited="true" ctrlrange="-200 200" />
		<motor name="l_mt_joint" joint="l_mt_joint" gear="1" ctrllimited="true" ctrlrange="-200 200" />
		<motor name="l_p_joint" joint="l_p_joint" gear="1" ctrllimited="true" ctrlrange="-200 200" />
		<motor name="l_wheel_joint" joint="l_wheel_joint" gear="1" ctrllimited="true" ctrlrange="-200 200" />
	</actuator>
	<sensor>
		<!-- Position sensors -->
		<actuatorpos name="r_mt_joint_p" actuator="r_mt_joint" user="13" />
		<actuatorpos name="r_p_joint_p" actuator="r_p_joint" user="13" />
		<actuatorpos name="r_wheel_joint_p" actuator="r_wheel_joint" user="13" />
		<actuatorpos name="l_mt_joint_p" actuator="l_mt_joint" user="13" />
		<actuatorpos name="l_p_joint_p" actuator="l_p_joint" user="13" />
		<actuatorpos name="l_wheel_joint_p" actuator="l_wheel_joint" user="13" />
		<!-- Velocity sensors -->
		<actuatorvel name="r_mt_joint_v" actuator="r_mt_joint" user="13" noise="1e-3" />
		<actuatorvel name="r_p_joint_v" actuator="r_p_joint" user="13" noise="1e-3" />
		<actuatorvel name="r_wheel_joint_v" actuator="r_wheel_joint" user="13" noise="1e-3" />
		<actuatorvel name="l_mt_joint_v" actuator="l_mt_joint" user="13" noise="1e-3" />
		<actuatorvel name="l_p_joint_v" actuator="l_p_joint" user="13" noise="1e-3" />
		<actuatorvel name="l_wheel_joint_v" actuator="l_wheel_joint" user="13" noise="1e-3" />
		<!-- Force sensors -->
		<actuatorfrc name="r_mt_joint_f" actuator="r_mt_joint" user="13" noise="1e-3" />
		<actuatorfrc name="r_p_joint_f" actuator="r_p_joint" user="13" noise="1e-3" />
		<actuatorfrc name="r_wheel_joint_f" actuator="r_wheel_joint" user="13" noise="1e-3" />
		<actuatorfrc name="l_mt_joint_f" actuator="l_mt_joint" user="13" noise="1e-3" />
		<actuatorfrc name="l_p_joint_f" actuator="l_p_joint" user="13" noise="1e-3" />
		<actuatorfrc name="l_wheel_joint_f" actuator="l_wheel_joint" user="13" noise="1e-3" />
		<framequat name="orientation" objtype="site" noise="0.001" objname="imu" />
		<framepos name="position" objtype="site" noise="0.001" objname="imu" />
		<gyro name="angular-velocity" site="imu" noise="0.005" cutoff="34.9" />
		<velocimeter name="linear-velocity" site="imu" noise="0.001" cutoff="30" />
		<accelerometer name="linear-acceleration" site="imu" noise="0.005" cutoff="157" />
		<magnetometer name="magnetometer" site="imu" />
	</sensor>
</mujoco>
