<?xml version="1.0" encoding="utf-8"?>
<!--
This URDF was automatically created by SolidWorks to URDF Exporter! Originally created by Stephen Brawner (brawner@gmail.com)
Commit Version: 1.6.0-4-g7f85cfe  Build Version: 1.6.7995.38578
For more information, please see http://wiki.ros.org/sw_urdf_exporter
-->
<robot name="hector_gazebo">

	<transmission name="l_f_mt_tran">
		<type>transmission_interface/SimpleTransmission</type>
		<joint name="l_f_mt_joint">
			<hardwareInterface>hardware_interface/EffortJointInterface</hardwareInterface>
		</joint>
		<actuator name="l_f_mt_motor">
			<hardwareInterface>hardware_interface/EffortJointInterface</hardwareInterface>
			<mechanicalReduction>1</mechanicalReduction>
		</actuator>
	</transmission>

	<transmission name="l_b_mt_tran">
		<type>transmission_interface/SimpleTransmission</type>
		<joint name="l_b_mt_joint">
			<hardwareInterface>hardware_interface/EffortJointInterface</hardwareInterface>
		</joint>
		<actuator name="l_b_mt_motor">
			<hardwareInterface>hardware_interface/EffortJointInterface</hardwareInterface>
			<mechanicalReduction>1</mechanicalReduction>
		</actuator>
	</transmission>

	<transmission name="l_wheel_tran">
		<type>transmission_interface/SimpleTransmission</type>
		<joint name="l_wheel_joint">
			<hardwareInterface>hardware_interface/EffortJointInterface</hardwareInterface>
		</joint>
		<actuator name="l_wheel_motor">
			<hardwareInterface>hardware_interface/EffortJointInterface</hardwareInterface>
			<mechanicalReduction>1</mechanicalReduction>
		</actuator>
	</transmission>

	<transmission name="r_f_mt_tran">
		<type>transmission_interface/SimpleTransmission</type>
		<joint name="r_f_mt_joint">
			<hardwareInterface>hardware_interface/EffortJointInterface</hardwareInterface>
		</joint>
		<actuator name="r_f_mt_motor">
			<hardwareInterface>hardware_interface/EffortJointInterface</hardwareInterface>
			<mechanicalReduction>1</mechanicalReduction>
		</actuator>
	</transmission>

	<transmission name="r_b_mt_tran">
		<type>transmission_interface/SimpleTransmission</type>
		<joint name="r_b_mt_joint">
			<hardwareInterface>hardware_interface/EffortJointInterface</hardwareInterface>
		</joint>
		<actuator name="r_b_mt_motor">
			<hardwareInterface>hardware_interface/EffortJointInterface</hardwareInterface>
			<mechanicalReduction>1</mechanicalReduction>
		</actuator>
	</transmission>

	<transmission name="r_wheel_tran">
		<type>transmission_interface/SimpleTransmission</type>
		<joint name="r_wheel_joint">
			<hardwareInterface>hardware_interface/EffortJointInterface</hardwareInterface>
		</joint>
		<actuator name="r_wheel_motor">
			<hardwareInterface>hardware_interface/EffortJointInterface</hardwareInterface>
			<mechanicalReduction>1</mechanicalReduction>
		</actuator>
	</transmission>

	<!-- <link name="virtual_pitch_link">
	</link> -->
	<!-- <joint name="base_link_virtual_pitch_joint" type="revolute">
		<origin xyz="0.0 0 0" rpy="0 0 0" />
		<parent link="virtual_pitch_link" />
		<child link="base_link" />
		<axis xyz="0 1 0" />
		<limit lower="-3.14" upper="3.14" effort="21" velocity="21" />
	</joint> -->

	<link name="base_link">
		<inertial>
			<origin xyz="-0.00044958 -1.247E-05 -0.0266506" rpy="0 0 0" />
			<mass value="6.23175715" />
			<inertia ixx="0.13614361" ixy="-0.00014781" ixz="-0.00043513" iyy="0.06800572" iyz="-0.00028023" izz="0.18109383" />
		</inertial>
		<visual>
			<origin xyz="0 0 0" rpy="0 0 0" />
			<geometry>
				<mesh filename="package://ph_0320_01/meshes/base_link.STL" />
			</geometry>
			<material name="">
				<color rgba="0.75294 0.75294 0.75294 1" />
			</material>
		</visual>
		<collision>
			<!-- <origin xyz="0 0 0" rpy="0 0 0" />
			<geometry>
				<mesh filename="package://ph_0320_01/meshes/base_link.STL" />
			</geometry> -->
			<origin xyz="0 0 0" rpy="0 0 0" />
			<geometry>
				<box size="0.1 0.1 0.1" />
			</geometry>

		</collision>
	</link>

	<link name="front_wheel_link">
		<inertial>
			<origin xyz="0 0 0" rpy="0 0 0" />
			<mass value="0.0001" />
			<inertia ixx="0" ixy="0" ixz="0" iyy="0" iyz="0" izz="0" />
		</inertial>
		<visual>
			<origin xyz="0 0 0" rpy="0 0 0" />
			<geometry>
				<sphere radius="0.03"/>
			</geometry>
		</visual>
		<collision>
			<origin xyz="0 0 0" rpy="0 0 0" />
			<geometry>
				<sphere radius="0.03"/>
			</geometry>
		</collision>
	</link>
	<joint name="front_wheel_joint" type="continuous">
		<origin xyz="0.25 0 -0.1" rpy="0 0 0" />
		<parent link="base_link" />
		<child link="front_wheel_link" />
		<axis xyz="0 1 0" />
		<limit effort="21" velocity="21" />
	</joint>

	<link name="back_wheel_link">
		<inertial>
			<origin xyz="0 0 0" rpy="0 0 0" />
			<mass value="0.0001" />
			<inertia ixx="0" ixy="0" ixz="0" iyy="0" iyz="0" izz="0" />
		</inertial>
		<visual>
			<origin xyz="0 0 0" rpy="0 0 0" />
			<geometry>
				<sphere radius="0.03" />
			</geometry>
		</visual>
		<collision>
			<origin xyz="0 0 0" rpy="0 0 0" />
			<geometry>
				<sphere radius="0.03" />
			</geometry>
		</collision>
	</link>
	<joint name="back_wheel_joint" type="continuous">
		<origin xyz="-0.25 0 -0.1" rpy="0 0 0" />
		<parent link="base_link" />
		<child link="back_wheel_link" />
		<axis xyz="0 1 0" />
		<limit effort="21" velocity="21" />
	</joint>

	<link name="l_f_mt_link">
		<inertial>
			<origin xyz="0.065203 -0.0075 -0.012318" rpy="0 0 0" />
			<mass value="0.1952" />
			<inertia ixx="6.5309E-05" ixy="-1.1987E-18" ixz="0.00010178" iyy="0.00071046" iyz="2.2543E-19" izz="0.00065247" />
		</inertial>
		<visual>
			<origin xyz="0 0 0" rpy="0 0 0" />
			<geometry>
				<mesh filename="package://ph_0320_01/meshes/l_f_mt_link.STL" />
			</geometry>
			<material name="">
				<color rgba="0.89804 0.91765 0.92941 1" />
			</material>
		</visual>
		<collision>
			<!-- <origin xyz="0 0 0" rpy="0 0 0" />
			<geometry>
				<mesh filename="package://ph_0320_01/meshes/l_f_mt_link.STL" />
			</geometry> -->
			<origin xyz="0 0 0" rpy="0 0 0" />
			<geometry>
				<box size="0.01 0.01 0.01" />
			</geometry>
		</collision>
	</link>
	<joint name="l_f_mt_joint" type="revolute">
		<origin xyz="0.054 0.2025 0" rpy="0 0 0" />
		<parent link="base_link" />
		<child link="l_f_mt_link" />
		<axis xyz="0 1 0" />
		<limit lower="-0.5" upper="1.3" effort="21" velocity="21" />
	</joint>
	<link name="l_f_calf_link">
		<inertial>
			<origin xyz="-0.10183 -0.024 -0.072928" rpy="0 0 0" />
			<mass value="0.33548" />
			<inertia ixx="0.00092843" ixy="1.5198E-19" ixz="-0.0012109" iyy="0.0027191" iyz="1.3188E-19" izz="0.0018032" />
		</inertial>
		<visual>
			<origin xyz="0 0 0" rpy="0 0 0" />
			<geometry>
				<mesh filename="package://ph_0320_01/meshes/l_f_calf_link.STL" />
			</geometry>
			<material name="">
				<color rgba="0.89804 0.91765 0.92941 1" />
			</material>
		</visual>
		<collision>
			<origin xyz="0 0 0" rpy="0 0 0" />
			<geometry>
				<box size="0.01 0.01 0.01" />
			</geometry>
			<!-- <origin xyz="0 0 0" rpy="0 0 0" />
			<geometry>
				<mesh filename="package://ph_0320_01/meshes/l_f_calf_link.STL" />
			</geometry> -->
		</collision>
	</link>
	<joint name="l_f_calf_joint" type="continuous">
		<origin xyz="0.14759 0 -0.026755" rpy="0 0 0" />
		<parent link="l_f_mt_link" />
		<child link="l_f_calf_link" />
		<axis xyz="0 1 0" />
	</joint>
	<link name="l_f_ankle_link">
		<inertial>
			<origin xyz="-1.3097E-14 -0.013355 -9.7145E-16" rpy="0 0 0" />
			<mass value="0.058741" />
			<inertia ixx="8.5044E-06" ixy="1.2172E-21" ixz="1.131E-21" iyy="1.4613E-05" iyz="2.3265E-21" izz="8.5044E-06" />
		</inertial>
		<visual>
			<origin xyz="0 0 0" rpy="0 0 0" />
			<geometry>
				<mesh filename="package://ph_0320_01/meshes/l_f_ankle_link.STL" />
			</geometry>
			<material name="">
				<color rgba="0.64706 0.61961 0.58824 1" />
			</material>
		</visual>
		<collision>
			<origin xyz="0.0 -0.02 0" rpy="0 0 0" />
			<geometry>
				<box size="0.01 0.01 0.01" />
			</geometry>
			<!-- <origin xyz="0 0 0" rpy="0 0 0" />
			<geometry>
				<mesh filename="package://ph_0320_01/meshes/l_f_ankle_link.STL" />
			</geometry> -->
		</collision>
	</link>
	<joint name="l_f_ankle_joint" type="fixed">
		<origin xyz="-0.20382 0 -0.14477" rpy="0 0 0" />
		<parent link="l_f_calf_link" />
		<child link="l_f_ankle_link" />
		<axis xyz="0 1 0" />
	</joint>
	<link name="l_wheel_link">
		<inertial>
			<origin xyz="6.7739E-06 -0.003652 4.26E-06" rpy="0 0 0" />
			<mass value="0.43397" />
			<inertia ixx="0.0005395" ixy="-3.2822E-08" ixz="1.2521E-08" iyy="0.0010009" iyz="2.8724E-09" izz="0.0005395" />
		</inertial>
		<visual>
			<origin xyz="0 0 0" rpy="0 0 0" />
			<!-- <origin xyz="0 -0.01 0" rpy="1.570796327948966 0 0" /> -->
			<geometry>
				<mesh filename="package://ph_0320_01/meshes/l_wheel_link.STL" />
				<!-- <cylinder radius="0.0725" length="0.03" /> -->
			</geometry>
			<material name="">
				<color rgba="0 1 1 1" />
			</material>
		</visual>
		<collision>
			<origin xyz="0 0 0" rpy="0 0 0" />
			<!-- <origin xyz="0 -0.01 0" rpy="1.570796327948966 0 0" /> -->
			<geometry>
				<mesh filename="package://ph_0320_01/meshes/l_wheel_link.STL" />
				<!-- <cylinder radius="0.0725" length="0.03" /> -->
			</geometry>
		</collision>
	</link>
	<joint name="l_wheel_joint" type="continuous">
		<origin xyz="0 0.0562 0" rpy="0 0 0" />
		<parent link="l_f_ankle_link" />
		<child link="l_wheel_link" />
		<axis xyz="0 1 0" />
		<limit effort="21" velocity="210" />
	</joint>
	<link name="l_b_mt_link">
		<inertial>
			<origin xyz="-0.065581 -0.0185 -0.010115" rpy="0 0 0" />
			<mass value="0.1952" />
			<inertia ixx="5.9126E-05" ixy="2.3573E-19" ixz="-8.179E-05" iyy="0.00071046" iyz="9.8375E-20" izz="0.00065865" />
		</inertial>
		<visual>
			<origin xyz="0 0 0" rpy="0 0 0" />
			<geometry>
				<mesh filename="package://ph_0320_01/meshes/l_b_mt_link.STL" />
			</geometry>
			<material name="">
				<color rgba="0.89804 0.91765 0.92941 1" />
			</material>
		</visual>
		<collision>
			<origin xyz="0.0 0.0 0" rpy="0 0 0" />
			<geometry>
				<box size="0.01 0.01 0.01" />
			</geometry>
			<!-- <origin xyz="0 0 0" rpy="0 0 0" />
			<geometry>
				<mesh filename="package://ph_0320_01/meshes/l_b_mt_link.STL" />
			</geometry> -->
		</collision>
	</link>
	<joint name="l_b_mt_joint" type="revolute">
		<origin xyz="-0.054 0.2025 0" rpy="0 0 0" />
		<parent link="base_link" />
		<child link="l_b_mt_link" />
		<axis xyz="0 1 0" />
		<limit lower="-1.3" upper="0.5" effort="21" velocity="21" />
	</joint>
	<link name="l_b_calf_link">
		<inertial>
			<origin xyz="0.1018 -0.002 -0.075545" rpy="0 0 0" />
			<mass value="0.33882" />
			<inertia ixx="0.0010466" ixy="2.1185E-19" ixz="0.0012744" iyy="0.0028007" iyz="-1.5746E-19" izz="0.0017669" />
		</inertial>
		<visual>
			<origin xyz="0 0 0" rpy="0 0 0" />
			<geometry>
				<mesh filename="package://ph_0320_01/meshes/l_b_calf_link.STL" />
			</geometry>
			<material name="">
				<color rgba="0.89804 0.91765 0.92941 1" />
			</material>
		</visual>
		<collision>
			<origin xyz="0.0 0.0 0" rpy="0 0 0" />
			<geometry>
				<box size="0.01 0.01 0.01" />
			</geometry>
			<!-- <origin xyz="0 0 0" rpy="0 0 0" />
			<geometry>
				<mesh filename="package://ph_0320_01/meshes/l_b_calf_link.STL" />
			</geometry> -->
		</collision>
	</link>
	<joint name="l_b_calf_joint" type="continuous">
		<origin xyz="-0.14841 0 -0.021771" rpy="0 0 0" />
		<parent link="l_b_mt_link" />
		<child link="l_b_calf_link" />
		<axis xyz="0 1 0" />
	</joint>
	<link name="l_b_ankle_link">
		<inertial>
			<origin xyz="4.4235E-16 0.011 8.3267E-17" rpy="0 0 0" />
			<mass value="0.035754" />
			<inertia ixx="7.9369E-06" ixy="6.0657E-22" ixz="2.482E-21" iyy="1.5153E-05" iyz="7.0455E-22" izz="7.9369E-06" />
		</inertial>
		<visual>
			<origin xyz="0 0 0" rpy="0 0 0" />
			<geometry>
				<mesh filename="package://ph_0320_01/meshes/l_b_ankle_link.STL" />
			</geometry>
			<material name="">
				<color rgba="0.89804 0.91765 0.92941 1" />
			</material>
		</visual>
		<collision>
			<origin xyz="0.0 0.02 0" rpy="0 0 0" />
			<geometry>
				<box size="0.01 0.01 0.01" />
			</geometry>
			<!-- <origin xyz="0 0 0" rpy="0 0 0" />
			<geometry>
				<mesh filename="package://ph_0320_01/meshes/l_b_ankle_link.STL" />
			</geometry> -->
		</collision>
	</link>
	<joint name="l_b_ankle_joint" type="continuous">
		<origin xyz="0.20019 0 -0.14975" rpy="0 0 0" />
		<parent link="l_b_calf_link" />
		<child link="l_b_ankle_link" />
		<axis xyz="0 1 0" />
		<limit effort="21" velocity="210" />
	</joint>
	<link name="r_f_mt_link">
		<inertial>
			<origin xyz="0.065203 0.0075 -0.012318" rpy="0 0 0" />
			<mass value="0.1952" />
			<inertia ixx="6.5309E-05" ixy="1.1742E-18" ixz="0.00010178" iyy="0.00071046" iyz="-2.1495E-19" izz="0.00065247" />
		</inertial>
		<visual>
			<origin xyz="0 0 0" rpy="0 0 0" />
			<geometry>
				<mesh filename="package://ph_0320_01/meshes/r_f_mt_link.STL" />
			</geometry>
			<material name="">
				<color rgba="0.89804 0.91765 0.92941 1" />
			</material>
		</visual>
		<collision>
			<origin xyz="0.0 0.0 0" rpy="0 0 0" />
			<geometry>
				<box size="0.01 0.01 0.01" />
			</geometry>
			<!-- <origin xyz="0 0 0" rpy="0 0 0" />
			<geometry>
				<mesh filename="package://ph_0320_01/meshes/r_f_mt_link.STL" />
			</geometry> -->
		</collision>
	</link>
	<joint name="r_f_mt_joint" type="revolute">
		<origin xyz="0.054 -0.2025 0" rpy="0 0 0" />
		<parent link="base_link" />
		<child link="r_f_mt_link" />
		<axis xyz="0 1 0" />
		<limit lower="-0.5" upper="1.3" effort="21" velocity="21" />
	</joint>
	<link name="r_f_calf_link">
		<inertial>
			<origin xyz="-0.10183 0.024 -0.072928" rpy="0 0 0" />
			<mass value="0.33548" />
			<inertia ixx="0.00092843" ixy="5.3701E-20" ixz="-0.0012109" iyy="0.0027191" iyz="5.5085E-20" izz="0.0018032" />
		</inertial>
		<visual>
			<origin xyz="0 0 0" rpy="0 0 0" />
			<geometry>
				<mesh filename="package://ph_0320_01/meshes/r_f_calf_link.STL" />
			</geometry>
			<material name="">
				<color rgba="0.89804 0.91765 0.92941 1" />
			</material>
		</visual>
		<collision>
			<origin xyz="0.0 0.0 0" rpy="0 0 0" />
			<geometry>
				<box size="0.01 0.01 0.01" />
			</geometry>
			<!-- <origin xyz="0 0 0" rpy="0 0 0" />
			<geometry>
				<mesh filename="package://ph_0320_01/meshes/r_f_calf_link.STL" />
			</geometry> -->
		</collision>
	</link>
	<joint name="r_f_calf_joint" type="continuous">
		<origin xyz="0.14759 0 -0.026755" rpy="0 0 0" />
		<parent link="r_f_mt_link" />
		<child link="r_f_calf_link" />
		<axis xyz="0 1 0" />
	</joint>
	<link name="r_f_ankle_link">
		<inertial>
			<origin xyz="-1.3076E-14 0.013355 -9.992E-16" rpy="0 0 0" />
			<mass value="0.058741" />
			<inertia ixx="8.5044E-06" ixy="1.3112E-21" ixz="1.5879E-21" iyy="1.4613E-05" iyz="-1.2581E-21" izz="8.5044E-06" />
		</inertial>
		<visual>
			<origin xyz="0 0 0" rpy="0 0 0" />
			<geometry>
				<mesh filename="package://ph_0320_01/meshes/r_f_ankle_link.STL" />
			</geometry>
			<material name="">
				<color rgba="0.64706 0.61961 0.58824 1" />
			</material>
		</visual>
		<collision>
			<origin xyz="0.0 0.02 0" rpy="0 0 0" />
			<geometry>
				<box size="0.01 0.01 0.01" />
			</geometry>
			<!-- <origin xyz="0 0 0" rpy="0 0 0" />
			<geometry>
				<mesh filename="package://ph_0320_01/meshes/r_f_ankle_link.STL" />
			</geometry> -->
		</collision>
	</link>
	<joint name="r_f_ankle_joint" type="fixed">
		<origin xyz="-0.20382 0 -0.14477" rpy="0 0 0" />
		<parent link="r_f_calf_link" />
		<child link="r_f_ankle_link" />
		<axis xyz="0 1 0" />
	</joint>
	<link name="r_wheel_link">
		<inertial>
			<origin xyz="-2.3366E-06 0.0089279 -8.278E-06" rpy="0 0 0" />
			<mass value="0.40373" />
			<inertia ixx="0.00044034" ixy="1.2024E-08" ixz="8.7688E-09" iyy="0.00081663" iyz="-3.0675E-08" izz="0.00044036" />
		</inertial>
		<visual>
			<origin xyz="0 0 0" rpy="0 0 0" />
			<geometry>
				<mesh filename="package://ph_0320_01/meshes/r_wheel_link.STL" />
				<!-- <cylinder radius="0.0725" length="0.03" /> -->
			</geometry>
			<material name="">
				<color rgba="0.29804 0.29804 0.29804 1" />
			</material>
		</visual>
		<collision>
			<!-- <origin xyz="0 0.01 0" rpy="1.570796327948966 0 0" /> -->
			<origin xyz="0 0 0" rpy="0 0 0" />
			<geometry>
				<mesh filename="package://ph_0320_01/meshes/r_wheel_link.STL" />
				<!-- <cylinder radius="0.0725" length="0.03" /> -->
			</geometry>
		</collision>
	</link>
	<joint name="r_wheel_joint" type="continuous">
		<origin xyz="0 -0.0562 0" rpy="0 0 0" />
		<parent link="r_f_ankle_link" />
		<child link="r_wheel_link" />
		<axis xyz="0 1 0" />
		<limit effort="21" velocity="210" />
	</joint>
	<link name="r_b_mt_link">
		<inertial>
			<origin xyz="-0.065581 0.0185 -0.010115" rpy="0 0 0" />
			<mass value="0.1952" />
			<inertia ixx="5.9126E-05" ixy="-9.0948E-20" ixz="-8.179E-05" iyy="0.00071046" iyz="-8.6667E-20" izz="0.00065865" />
		</inertial>
		<visual>
			<origin xyz="0 0 0" rpy="0 0 0" />
			<geometry>
				<mesh filename="package://ph_0320_01/meshes/r_b_mt_link.STL" />
			</geometry>
			<material name="">
				<color rgba="0.89804 0.91765 0.92941 1" />
			</material>
		</visual>
		<collision>
			<origin xyz="0.0 0.0 0" rpy="0 0 0" />
			<geometry>
				<box size="0.01 0.01 0.01" />
			</geometry>
			<!-- <origin xyz="0 0 0" rpy="0 0 0" />
			<geometry>
				<mesh filename="package://ph_0320_01/meshes/r_b_mt_link.STL" />
			</geometry> -->
		</collision>
	</link>
	<joint name="r_b_mt_joint" type="revolute">
		<origin xyz="-0.054 -0.2025 0" rpy="0 0 0" />
		<parent link="base_link" />
		<child link="r_b_mt_link" />
		<axis xyz="0 1 0" />
		<limit lower="-1.3" upper="0.5" effort="21" velocity="21" />
	</joint>
	<link name="r_b_calf_link">
		<inertial>
			<origin xyz="0.1018 0.002 -0.075545" rpy="0 0 0" />
			<mass value="0.33882" />
			<inertia ixx="0.0010466" ixy="-5.0995E-19" ixz="0.0012744" iyy="0.0028007" iyz="3.0887E-19" izz="0.0017669" />
		</inertial>
		<visual>
			<origin xyz="0 0 0" rpy="0 0 0" />
			<geometry>
				<mesh filename="package://ph_0320_01/meshes/r_b_calf_link.STL" />
			</geometry>
			<material name="">
				<color rgba="0.89804 0.91765 0.92941 1" />
			</material>
		</visual>
		<collision>
			<origin xyz="0.0 0.0 0" rpy="0 0 0" />
			<geometry>
				<box size="0.01 0.01 0.01" />
			</geometry>
			<!-- <origin xyz="0 0 0" rpy="0 0 0" />
			<geometry>
				<mesh filename="package://ph_0320_01/meshes/r_b_calf_link.STL" />
			</geometry> -->
		</collision>
	</link>
	<joint name="r_b_calf_joint" type="continuous">
		<origin xyz="-0.14841 0 -0.021771" rpy="0 0 0" />
		<parent link="r_b_mt_link" />
		<child link="r_b_calf_link" />
		<axis xyz="0 1 0" />
	</joint>
	<link name="r_b_ankle_link">
		<inertial>
			<origin xyz="4.0766E-16 -0.011 2.7756E-17" rpy="0 0 0" />
			<mass value="0.035754" />
			<inertia ixx="7.9369E-06" ixy="-3.4059E-22" ixz="9.4221E-22" iyy="1.5153E-05" iyz="-7.1044E-22" izz="7.9369E-06" />
		</inertial>
		<visual>
			<origin xyz="0 0 0" rpy="0 0 0" />
			<geometry>
				<mesh filename="package://ph_0320_01/meshes/r_b_ankle_link.STL" />
			</geometry>
			<material name="">
				<color rgba="0.89804 0.91765 0.92941 1" />
			</material>
		</visual>
		<collision>
			<origin xyz="0.0 -0.02 0" rpy="0 0 0" />
			<geometry>
				<box size="0.01 0.01 0.01" />
			</geometry>
			<!-- <origin xyz="0 0 0" rpy="0 0 0" />
			<geometry>
				<mesh filename="package://ph_0320_01/meshes/r_b_ankle_link.STL" />
			</geometry> -->
		</collision>
	</link>
	<joint name="r_b_ankle_joint" type="continuous">
		<origin xyz="0.20019 0 -0.14975" rpy="0 0 0" />
		<parent link="r_b_calf_link" />
		<child link="r_b_ankle_link" />
		<axis xyz="0 1 0" />
		<limit effort="21" velocity="210" />
	</joint>
	<gazebo>
		<plugin name="gazebo_ros_control" filename="libgazebo_ros_control.so">
			<robotNamespace>/hector_gazebo</robotNamespace>
			<robotSimType>gazebo_ros_control/DefaultRobotHWSim</robotSimType>
		</plugin>
	</gazebo>

	<gazebo>
		<joint name="r_ankle" type="fixed">
			<pose relative_to="r_b_ankle_link"> 0.0 0. 0.0 0 0 0 </pose>
			<parent>r_b_ankle_link</parent>
			<child>r_wheel_link</child>
		</joint>
	</gazebo>

	<gazebo>
		<joint name="l_ankle" type="fixed">
			<pose relative_to="l_b_ankle_link"> 0.0 0 0.0 0 0 0 </pose>
			<parent>l_b_ankle_link</parent>
			<child>l_wheel_link</child>
		</joint>
	</gazebo>

	<joint name="imu_joint" type="fixed">
		<parent link="base_link"/>
		<child link="imu_link"/>
		<origin rpy="0 0 0" xyz="0 0 0"/>
	</joint>

	<link name="imu_link">
		<inertial>
			<mass value="0.001"/>
			<origin rpy="0 0 0" xyz="0 0 0"/>
			<inertia ixx="0.0001" ixy="0" ixz="0" iyy="0.0001" iyz="0" izz="0.0001"/>
		</inertial>
		<visual>
			<origin rpy="0 0 0" xyz="0 0 0"/>
			<geometry>
				<box size="0.001 0.001 0.001"/>
			</geometry>
			<material name="red"/>
		</visual>
		<collision>
			<origin rpy="0 0 0" xyz="0 0 0"/>
			<geometry>
				<box size=".001 .001 .001"/>
			</geometry>
		</collision>
	</link>
	<gazebo>
		<plugin name="imu_plugin" filename="libgazebo_ros_imu.so">
			<alwaysOn>true</alwaysOn>
			<bodyName>imu_link</bodyName>
			<topicName>imu</topicName>
			<serviceName>imu_service</serviceName>
			<gaussianNoise>0.0</gaussianNoise>
			<updateRate>1000.0</updateRate>
		</plugin>
	</gazebo>
	<!-- <gazebo reference="imu_link">
		<sensor name="imu_sensor" type="imu">
			<plugin filename="libgazebo_ros_imu_sensor.so" name="imu_plugin">
				<topicName>imu</topicName>
				<initial_orientation_as_reference>true</initial_orientation_as_reference>
			</plugin>
			<always_on>true</always_on>
			<update_rate>1000</update_rate>
			<visualize>true</visualize>
		</sensor>
	</gazebo> -->


	<!-- <gazebo>
		<joint name="base_link_fixed_joint" type="fixed">
			<pose relative_to="base_link"> 0.0 0.0 0. 0 0 0 </pose>
			<parent>world</parent>
			<child>base_link</child>
		</joint>
	</gazebo> -->


	<gazebo reference="r_wheel_link">
		<mu1>100</mu1>
		<mu2>50</mu2>
	</gazebo>
	<gazebo reference="l_wheel_link">
		<mu1>100</mu1>
		<mu2>50</mu2>
	</gazebo>

	<!-- <gazebo>
		<joint name="virtual_pitch_prismatic_joint" type="prismatic">
			<parent>world</parent>
			<child>base_link</child>
			<axis>
				<xyz>1 0 0 </xyz>
				<limit>
					<lower> -0.3</lower>
					<upper> 0.3 </upper>
					<effort> 1000000 </effort>
					<velocity> 100000000 </velocity>
				</limit>
			</axis>
		</joint>
	</gazebo> -->
	<gazebo>
		<joint name="r_wheel_link_fixed_joint" type="fixed">
			<parent>world</parent>
			<child>r_wheel_link</child>
		</joint>
	</gazebo>
	<gazebo>
		<joint name="l_wheel_link_fixed_joint" type="fixed">
			<parent>world</parent>
			<child>l_wheel_link</child>
		</joint>
	</gazebo>
</robot>
