<?xml version="1.0" encoding="utf-8"?>
<robot name="hector_gazebo">
	<mujoco>
		<compiler meshdir="../meshes/" balanceinertia="true" discardvisual="false" />
	</mujoco>
	<link name="base_link">
		<inertial>
			<origin xyz="-0.00044958 -1.247E-05 -0.0266506" rpy="0 0 0" />
			<mass value="6.23175715" />
			<inertia ixx="0.13614361" ixy="-0.00014781" ixz="-0.00043513" iyy="0.06800572" iyz="-0.00028023" izz="0.18109383" />
		</inertial>
		<visual>
			<origin xyz="0 0 0" rpy="0 0 0" />
			<geometry>
				<box size="0.28 0.28 0.12" />
				<!-- <mesh filename="../meshes/base_link.STL" /> -->
			</geometry>
			<material name="">
				<color rgba="0.75294 0.75294 0.75294 1" />
			</material>
		</visual>
		<collision>
			<!-- <origin xyz="0 0 0" rpy="0 0 0" />
			<geometry>
				<mesh filename="../meshes/base_link.STL" />
			</geometry> -->
			<origin xyz="0 0 0" rpy="0 0 0" />
			<geometry>
				<box size="0.28 0.28 0.12" />
			</geometry>

		</collision>
	</link>

	<link name="l_mt_link">
		<inertial>
			<origin xyz="0 0 0" rpy="0 0 0" />
			<mass value="0.0001" />
			<inertia ixx="1.0E-10" ixy="1.0E-10" ixz="1.0E-10" iyy="1.0E-10" iyz="1.0E-10" izz="1.0E-10" />
		</inertial>
		<visual>
			<origin xyz="0 0 -0.04" rpy="0 0 0" />
			<geometry>
				<box size="0.025 0.025 0.08" />
				<!-- <mesh filename="../meshes/l_f_mt_link.STL" /> -->
			</geometry>
			<material name="">
				<color rgba="0.3 0.4 0.5 1" />
			</material>
		</visual>
		<collision>
			<origin xyz="0 0 -0.04" rpy="0 0 0" />
			<geometry>
				<box size="0.025 0.025 0.08" />
				<!-- <box size="0.03 0.03 0.03" /> -->
			</geometry>
		</collision>
	</link>
	<joint name="l_mt_joint" type="revolute">
		<origin xyz="0.0 0.16 0" rpy="0 0 0" />
		<parent link="base_link" />
		<child link="l_mt_link" />
		<axis xyz="0 1 0" />
		<limit lower="-0.8" upper="0.8" effort="21" velocity="21" />
	</joint>

	<link name="l_p_link">
		<inertial>
			<origin xyz="0 0 0" rpy="0 0 0" />
			<mass value="0.0001" />
			<inertia ixx="1.0E-10" ixy="1.0E-10" ixz="1.0E-10" iyy="1.0E-10" iyz="1.0E-10" izz="1.0E-10" />
		</inertial>
		<visual>
			<origin xyz="0 0.03 -0.04" rpy="0 0 0" />
			<geometry>
				<box size="0.025 0.025 0.08" />
				<!-- <mesh filename="../meshes/l_f_mt_link.STL" /> -->
			</geometry>
			<material name="">
				<color rgba="0.4 0.3 0.2 1" />
			</material>
		</visual>
		<collision>
			<origin xyz="0 0.03 -0.04" rpy="0 0 0" />
			<geometry>
				<box size="0.025 0.025 0.08" />
			</geometry>
		</collision>
	</link>
	<joint name="l_p_joint" type="prismatic">
		<origin xyz="0.0 0.0 -0.08" rpy="0 0 0" />
		<parent link="l_mt_link" />
		<child link="l_p_link" />
		<axis xyz="0 0 1" />
		<limit lower="-0.18" upper="0.08" effort="400" velocity="0.5" />
	</joint>

	<link name="l_wheel_link">
		<inertial>
			<origin xyz="6.7739E-06 -0.003652 4.26E-06" rpy="0 0 0" />
			<mass value="0.43397" />
			<inertia ixx="0.0005395" ixy="-3.2822E-08" ixz="1.2521E-08" iyy="0.0010009" iyz="2.8724E-09" izz="0.0005395" />
		</inertial>
		<visual>
			<origin xyz="0 0 0" rpy="0 0 0" />
			<!-- <origin xyz="0 -0.01 0" rpy="1.570796327948966 0 0" /> -->
			<geometry>
				<mesh filename="../meshes/l_wheel_link.STL" />
				<!-- <cylinder radius="0.0725" length="0.03" /> -->
			</geometry>
			<material name="">
				<color rgba="0 1 1 1" />
			</material>
		</visual>
		<collision>
			<!-- <origin xyz="0 0 0" rpy="0 0 0" /> -->
			<origin xyz="0 -0.01 0" rpy="1.570796327948966 0 0" />
			<geometry>
				<!-- <mesh filename="../meshes/l_wheel_link.STL" /> -->
				<cylinder radius="0.0725" length="0.03" />
			</geometry>
		</collision>
	</link>
	<joint name="l_wheel_joint" type="revolute">
		<origin xyz="0 0.1 -0.091525" rpy="0 0 0" />
		<parent link="l_p_link" />
		<child link="l_wheel_link" />
		<axis xyz="0 1 0" />
		<!-- <limit effort="21" velocity="210" /> -->
		<limit lower="-1e5" upper="1e5" effort="10" velocity="30" />
	</joint>

	
	
	<link name="r_mt_link">
		<inertial>
			<origin xyz="0 0 0" rpy="0 0 0" />
			<mass value="0.0001" />
			<inertia ixx="1.0E-10" ixy="1.0E-10" ixz="1.0E-10" iyy="1.0E-10" iyz="1.0E-10" izz="1.0E-10" />
		</inertial>
		<visual>
			<origin xyz="0 0 -0.04" rpy="0 0 0" />
			<geometry>
				<box size="0.025 0.025 0.08" />
				<!-- <mesh filename="../meshes/l_f_mt_link.STL" /> -->
			</geometry>
			<material name="">
				<color rgba="0.3 0.4 0.5 1" />
			</material>
		</visual>
		<collision>
			<origin xyz="0 0 -0.04" rpy="0 0 0" />
			<geometry>
				<box size="0.025 0.025 0.08" />
				<!-- <box size="0.03 0.03 0.03" /> -->
			</geometry>
		</collision>
	</link>
	<joint name="r_mt_joint" type="revolute">
		<origin xyz="0.0 -0.16 0" rpy="0 0 0" />
		<parent link="base_link" />
		<child link="r_mt_link" />
		<axis xyz="0 1 0" />
		<limit lower="-0.8" upper="0.8" effort="21" velocity="21" />
	</joint>

	<link name="r_p_link">
		<inertial>
			<origin xyz="0 0 0" rpy="0 0 0" />
			<mass value="0.0001" />
			<inertia ixx="1.0E-10" ixy="1.0E-10" ixz="1.0E-10" iyy="1.0E-10" iyz="1.0E-10" izz="1.0E-10" />
		</inertial>
		<visual>
			<origin xyz="0 -0.03 -0.04" rpy="0 0 0" />
			<geometry>
				<box size="0.025 0.025 0.08" />
				<!-- <mesh filename="../meshes/l_f_mt_link.STL" /> -->
			</geometry>
			<material name="">
				<color rgba="0.4 0.3 0.2 1" />
			</material>
		</visual>
		<collision>
			<origin xyz="0 -0.03 -0.04" rpy="0 0 0" />
			<geometry>
				<box size="0.025 0.025 0.08" />
			</geometry>
		</collision>
	</link>
	<joint name="r_p_joint" type="prismatic">
		<origin xyz="0.0 0.0 -0.08" rpy="0 0 0" />
		<parent link="r_mt_link" />
		<child link="r_p_link" />
		<axis xyz="0 0 1" />
		<limit lower="-0.18" upper="0.08" effort="400" velocity="0.5" />
	</joint>

	<link name="r_wheel_link">
		<inertial>
			<origin xyz="-2.3366E-06 0.0089279 -8.278E-06" rpy="0 0 0" />
			<mass value="0.40373" />
			<inertia ixx="0.00044034" ixy="1.2024E-08" ixz="8.7688E-09" iyy="0.00081663" iyz="-3.0675E-08" izz="0.00044036" />
		</inertial>
		<visual>
			<origin xyz="0 0 0" rpy="0 0 0" />
			<geometry>
				<mesh filename="../meshes/r_wheel_link.STL" />
				<!-- <cylinder radius="0.0725" length="0.03" /> -->
			</geometry>
			<material name="">
				<color rgba="0.29804 0.29804 0.29804 1" />
			</material>
		</visual>
		<collision>
			<origin xyz="0 0.01 0" rpy="1.570796327948966 0 0" />
			<!-- <origin xyz="0 0 0" rpy="0 0 0" /> -->
			<geometry>
				<!-- <mesh filename="../meshes/r_wheel_link.STL" /> -->
				<cylinder radius="0.0725" length="0.03" />
			</geometry>
		</collision>
	</link>
	<joint name="r_wheel_joint" type="revolute">
		<origin xyz="0 -0.1 -0.091525" rpy="0 0 0" />
		<parent link="r_p_link" />
		<child link="r_wheel_link" />
		<axis xyz="0 1 0" />
		<limit lower="-1e5" upper="1e5" effort="10" velocity="30" />
	</joint>




	<link name="l_f_mt_link">
		<inertial>
			<origin xyz="0.065203 -0.0075 -0.012318" rpy="0 0 0" />
			<mass value="0.1952" />
			<inertia ixx="6.5309E-05" ixy="-1.1987E-18" ixz="0.00010178" iyy="0.00071046" iyz="2.2543E-19" izz="0.00065247" />
		</inertial>
		<visual>
			<origin xyz="0 0 0" rpy="0 0 0" />
			<geometry>
				<mesh filename="../meshes/l_f_mt_link.STL" />
			</geometry>
			<material name="">
				<color rgba="0.89804 0.91765 0.92941 1" />
			</material>
		</visual>
		<collision>
			<origin xyz="0 0 0" rpy="0 0 0" />
			<geometry>
				<mesh filename="../meshes/l_f_mt_link.STL" />
			</geometry>
			<!-- <origin xyz="0 0 0" rpy="0 0 0" />
			<geometry>
				<box size="0.01 0.01 0.01" />
			</geometry> -->
		</collision>
	</link>
	<joint name="l_f_mt_joint" type="fixed">
		<origin xyz="0.054 0.2025 0" rpy="0 0 0" />
		<parent link="base_link" />
		<child link="l_f_mt_link" />
		<axis xyz="0 1 0" />
		<!-- <limit lower="-0.5" upper="1.3" effort="21" velocity="21" /> -->
	</joint>
	
	<link name="l_b_mt_link">
		<inertial>
			<origin xyz="-0.065581 -0.0185 -0.010115" rpy="0 0 0" />
			<mass value="0.1952" />
			<inertia ixx="5.9126E-05" ixy="2.3573E-19" ixz="-8.179E-05" iyy="0.00071046" iyz="9.8375E-20" izz="0.00065865" />
		</inertial>
		<visual>
			<origin xyz="0 0 0" rpy="0 0 0" />
			<geometry>
				<mesh filename="../meshes/l_b_mt_link.STL" />
			</geometry>
			<material name="">
				<color rgba="0.89804 0.91765 0.92941 1" />
			</material>
		</visual>
		<collision>
			<!-- <origin xyz="0.0 0.0 0" rpy="0 0 0" />
			<geometry>
				<box size="0.01 0.01 0.01" />
			</geometry> -->
			<origin xyz="0 0 0" rpy="0 0 0" />
			<geometry>
				<mesh filename="../meshes/l_b_mt_link.STL" />
			</geometry>
		</collision>
	</link>
	<joint name="l_b_mt_joint" type="fixed">
		<origin xyz="-0.054 0.2025 0" rpy="0 0 0" />
		<parent link="base_link" />
		<child link="l_b_mt_link" />
		<axis xyz="0 1 0" />
		<limit lower="-1.3" upper="0.5" effort="21" velocity="21" />
	</joint>

	<link name="r_f_mt_link">
		<inertial>
			<origin xyz="0.065203 0.0075 -0.012318" rpy="0 0 0" />
			<mass value="0.1952" />
			<inertia ixx="6.5309E-05" ixy="1.1742E-18" ixz="0.00010178" iyy="0.00071046" iyz="-2.1495E-19" izz="0.00065247" />
		</inertial>
		<visual>
			<origin xyz="0 0 0" rpy="0 0 0" />
			<geometry>
				<mesh filename="../meshes/r_f_mt_link.STL" />
			</geometry>
			<material name="">
				<color rgba="0.89804 0.91765 0.92941 1" />
			</material>
		</visual>
		<collision>
			<!-- <origin xyz="0.0 0.0 0" rpy="0 0 0" />
			<geometry>
				<box size="0.01 0.01 0.01" />
			</geometry> -->
			<origin xyz="0 0 0" rpy="0 0 0" />
			<geometry>
				<mesh filename="../meshes/r_f_mt_link.STL" />
			</geometry>
		</collision>
	</link>
	<joint name="r_f_mt_joint" type="fixed">
		<origin xyz="0.054 -0.2025 0" rpy="0 0 0" />
		<parent link="base_link" />
		<child link="r_f_mt_link" />
		<axis xyz="0 1 0" />
		<limit lower="-0.5" upper="1.3" effort="21" velocity="21" />
	</joint>

	<link name="r_b_mt_link">
		<inertial>
			<origin xyz="-0.065581 0.0185 -0.010115" rpy="0 0 0" />
			<mass value="0.1952" />
			<inertia ixx="5.9126E-05" ixy="-9.0948E-20" ixz="-8.179E-05" iyy="0.00071046" iyz="-8.6667E-20" izz="0.00065865" />
		</inertial>
		<visual>
			<origin xyz="0 0 0" rpy="0 0 0" />
			<geometry>
				<mesh filename="../meshes/r_b_mt_link.STL" />
			</geometry>
			<material name="">
				<color rgba="0.89804 0.91765 0.92941 1" />
			</material>
		</visual>
		<collision>
			<!-- <origin xyz="0.0 0.0 0" rpy="0 0 0" />
			<geometry>
				<box size="0.01 0.01 0.01" />
			</geometry> -->
			<origin xyz="0 0 0" rpy="0 0 0" />
			<geometry>
				<mesh filename="../meshes/r_b_mt_link.STL" />
			</geometry>
		</collision>
	</link>
	<joint name="r_b_mt_joint" type="fixed">
		<origin xyz="-0.054 -0.2025 0" rpy="0 0 0" />
		<parent link="base_link" />
		<child link="r_b_mt_link" />
		<axis xyz="0 1 0" />
		<limit lower="-1.3" upper="0.5" effort="21" velocity="21" />
	</joint>
	
</robot>
